<?xml version="1.0" encoding="UTF-8"?><testsuite name="nosetests" tests="1" errors="0" failures="1" skip="0"><testcase classname="test_app_views.TestLocationsCard" name="test_wc_contact_args" time="72.190"><failure type="builtins.AssertionError" message="Expected call: get_device(&lt;pyramid.testing.DummyRequest object at 0x0000028E654AC388&gt;, 'GET', '/design/41/redeemers', anon=True)&#10;Actual call: get_device(&lt;pyramid.testing.DummyRequest object at 0x0000028E654AC388&gt;)"><![CDATA[Traceback (most recent call last):
  File "C:\Users\willi\AppData\Local\Programs\Python\Python37\lib\unittest\case.py", line 59, in testPartExecutor
    yield
  File "C:\Users\willi\AppData\Local\Programs\Python\Python37\lib\unittest\case.py", line 628, in run
    testMethod()
  File "C:\Users\willi\AppData\Local\Programs\Python\Python37\lib\unittest\mock.py", line 1209, in patched
    return func(*args, **keywargs)
  File "c:\Users\willi\Documents\Work\FerlySite\backend\appapi\views\tests\test_app_views.py", line 86, in test_wc_contact_args
    anon=True)
  File "C:\Users\willi\AppData\Local\Programs\Python\Python37\lib\unittest\mock.py", line 834, in assert_called_with
    raise AssertionError(_error_message()) from cause
AssertionError: Expected call: get_device(<pyramid.testing.DummyRequest object at 0x0000028E654AC388>, 'GET', '/design/41/redeemers', anon=True)
Actual call: get_device(<pyramid.testing.DummyRequest object at 0x0000028E654AC388>)
]]></failure></testcase></testsuite>