<?xml version="1.0" encoding="UTF-8"?><testsuite name="nosetests" tests="1" errors="0" failures="1" skip="0"><testcase classname="test_app_views.TestGetFerlyCashDesign" name="test_get_device_called" time="79.562"><failure type="builtins.AssertionError" message="Expected 'get_device' to have been called."><![CDATA[Traceback (most recent call last):
  File "C:\Users\willi\AppData\Local\Programs\Python\Python37\lib\unittest\case.py", line 59, in testPartExecutor
    yield
  File "C:\Users\willi\AppData\Local\Programs\Python\Python37\lib\unittest\case.py", line 628, in run
    testMethod()
  File "C:\Users\willi\AppData\Local\Programs\Python\Python37\lib\unittest\mock.py", line 1209, in patched
    return func(*args, **keywargs)
  File "c:\Users\willi\Documents\Work\FerlySite\backend\appapi\views\tests\test_app_views.py", line 151, in test_get_device_called
    get_device.assert_called()
  File "C:\Users\willi\AppData\Local\Programs\Python\Python37\lib\unittest\mock.py", line 806, in assert_called
    raise AssertionError(msg)
AssertionError: Expected 'get_device' to have been called.
]]></failure></testcase></testsuite>